INFO:root:Бот стартовал
ERROR:telegram.ext.dispatcher:No error handlers are registered, logging exception.
Traceback (most recent call last):
  File "c:\projects\bot_diplom\env\lib\site-packages\telegram\ext\dispatcher.py", line 340, in process_update
    handler.handle_update(update, self, check, context)
  File "c:\projects\bot_diplom\env\lib\site-packages\telegram\ext\conversationhandler.py", line 465, in handle_update
    new_state = handler.handle_update(update, dispatcher, check_result, context)
  File "c:\projects\bot_diplom\env\lib\site-packages\telegram\ext\handler.py", line 119, in handle_update
    return self.callback(update, context)
  File "c:\projects\bot_diplom\anketa_prod_owner.py", line 130, in anketa_own_contacts_end
    users = list(user['user_id'], context.user_data['anketa'])
TypeError: list expected at most 1 argument, got 2
INFO:telegram.ext.updater:Received signal 2 (SIGINT), stopping...
WARNING:telegram.ext.updater:Exiting immediately!
INFO:root:Бот стартовал
ERROR:telegram.ext.dispatcher:No error handlers are registered, logging exception.
Traceback (most recent call last):
  File "c:\projects\bot_diplom\env\lib\site-packages\telegram\ext\dispatcher.py", line 340, in process_update
    handler.handle_update(update, self, check, context)
  File "c:\projects\bot_diplom\env\lib\site-packages\telegram\ext\conversationhandler.py", line 465, in handle_update
    new_state = handler.handle_update(update, dispatcher, check_result, context)
  File "c:\projects\bot_diplom\env\lib\site-packages\telegram\ext\handler.py", line 119, in handle_update
    return self.callback(update, context)
  File "c:\projects\bot_diplom\anketa_prod_owner.py", line 130, in anketa_own_contacts_end
    users = list(user['user_id'], )
TypeError: 'int' object is not iterable
INFO:telegram.ext.updater:Received signal 2 (SIGINT), stopping...
WARNING:telegram.ext.updater:Exiting immediately!
INFO:root:Бот стартовал
ERROR:telegram.ext.dispatcher:No error handlers are registered, logging exception.
Traceback (most recent call last):
  File "c:\projects\bot_diplom\env\lib\site-packages\telegram\ext\dispatcher.py", line 340, in process_update
    handler.handle_update(update, self, check, context)
  File "c:\projects\bot_diplom\env\lib\site-packages\telegram\ext\conversationhandler.py", line 465, in handle_update
    new_state = handler.handle_update(update, dispatcher, check_result, context)
  File "c:\projects\bot_diplom\env\lib\site-packages\telegram\ext\handler.py", line 119, in handle_update
    return self.callback(update, context)
  File "c:\projects\bot_diplom\anketa_prod_owner.py", line 130, in anketa_own_contacts_end
    users = list(user['user_id'])
TypeError: 'int' object is not iterable
INFO:telegram.ext.updater:Received signal 2 (SIGINT), stopping...
WARNING:telegram.ext.updater:Exiting immediately!
INFO:root:Бот стартовал
ERROR:telegram.ext.dispatcher:No error handlers are registered, logging exception.
Traceback (most recent call last):
  File "c:\projects\bot_diplom\env\lib\site-packages\telegram\ext\dispatcher.py", line 340, in process_update
    handler.handle_update(update, self, check, context)
  File "c:\projects\bot_diplom\env\lib\site-packages\telegram\ext\conversationhandler.py", line 465, in handle_update
    new_state = handler.handle_update(update, dispatcher, check_result, context)
  File "c:\projects\bot_diplom\env\lib\site-packages\telegram\ext\handler.py", line 119, in handle_update
    return self.callback(update, context)
  File "c:\projects\bot_diplom\anketa_prod_owner.py", line 130, in anketa_own_contacts_end
    users = list(user['user_id'])
TypeError: 'int' object is not iterable
INFO:telegram.ext.updater:Received signal 2 (SIGINT), stopping...
WARNING:telegram.ext.updater:Exiting immediately!
INFO:root:Бот стартовал
INFO:telegram.ext.updater:Received signal 2 (SIGINT), stopping...
WARNING:telegram.ext.updater:Exiting immediately!
INFO:root:Бот стартовал
INFO:telegram.ext.updater:Received signal 2 (SIGINT), stopping...
WARNING:telegram.ext.updater:Exiting immediately!
INFO:root:Бот стартовал
ERROR:telegram.ext.dispatcher:No error handlers are registered, logging exception.
Traceback (most recent call last):
  File "c:\projects\bot_diplom\env\lib\site-packages\telegram\ext\dispatcher.py", line 340, in process_update
    handler.handle_update(update, self, check, context)
  File "c:\projects\bot_diplom\env\lib\site-packages\telegram\ext\conversationhandler.py", line 465, in handle_update
    new_state = handler.handle_update(update, dispatcher, check_result, context)
  File "c:\projects\bot_diplom\env\lib\site-packages\telegram\ext\handler.py", line 119, in handle_update
    return self.callback(update, context)
  File "c:\projects\bot_diplom\anketa_prod_owner.py", line 136, in anketa_own_contacts_end
    worksheet.append_row(users)
  File "c:\projects\bot_diplom\env\lib\site-packages\gspread\models.py", line 1437, in append_row
    return self.append_rows(
  File "c:\projects\bot_diplom\env\lib\site-packages\gspread\models.py", line 1478, in append_rows
    return self.spreadsheet.values_append(range_label, params, body)
  File "c:\projects\bot_diplom\env\lib\site-packages\gspread\models.py", line 164, in values_append
    r = self.client.request('post', url, params=params, json=body)
  File "c:\projects\bot_diplom\env\lib\site-packages\gspread\client.py", line 61, in request
    response = getattr(self.session, method)(
  File "c:\projects\bot_diplom\env\lib\site-packages\requests\sessions.py", line 590, in post
    return self.request('POST', url, data=data, json=json, **kwargs)
  File "c:\projects\bot_diplom\env\lib\site-packages\google\auth\transport\requests.py", line 464, in request
    response = super(AuthorizedSession, self).request(
  File "c:\projects\bot_diplom\env\lib\site-packages\requests\sessions.py", line 528, in request
    prep = self.prepare_request(req)
  File "c:\projects\bot_diplom\env\lib\site-packages\requests\sessions.py", line 456, in prepare_request
    p.prepare(
  File "c:\projects\bot_diplom\env\lib\site-packages\requests\models.py", line 319, in prepare
    self.prepare_body(data, files, json)
  File "c:\projects\bot_diplom\env\lib\site-packages\requests\models.py", line 469, in prepare_body
    body = complexjson.dumps(json)
  File "C:\Users\Admin\AppData\Local\Programs\Python\Python38\lib\json\__init__.py", line 231, in dumps
    return _default_encoder.encode(obj)
  File "C:\Users\Admin\AppData\Local\Programs\Python\Python38\lib\json\encoder.py", line 199, in encode
    chunks = self.iterencode(o, _one_shot=True)
  File "C:\Users\Admin\AppData\Local\Programs\Python\Python38\lib\json\encoder.py", line 257, in iterencode
    return _iterencode(o, 0)
  File "C:\Users\Admin\AppData\Local\Programs\Python\Python38\lib\json\encoder.py", line 179, in default
    raise TypeError(f'Object of type {o.__class__.__name__} '
TypeError: Object of type datetime is not JSON serializable
INFO:telegram.ext.updater:Received signal 2 (SIGINT), stopping...
WARNING:telegram.ext.updater:Exiting immediately!
INFO:root:Бот стартовал
ERROR:telegram.ext.dispatcher:No error handlers are registered, logging exception.
Traceback (most recent call last):
  File "c:\projects\bot_diplom\env\lib\site-packages\telegram\ext\dispatcher.py", line 340, in process_update
    handler.handle_update(update, self, check, context)
  File "c:\projects\bot_diplom\env\lib\site-packages\telegram\ext\conversationhandler.py", line 465, in handle_update
    new_state = handler.handle_update(update, dispatcher, check_result, context)
  File "c:\projects\bot_diplom\env\lib\site-packages\telegram\ext\handler.py", line 119, in handle_update
    return self.callback(update, context)
  File "c:\projects\bot_diplom\anketa_prod_owner.py", line 136, in anketa_own_contacts_end
    worksheet.append_row(users)
  File "c:\projects\bot_diplom\env\lib\site-packages\gspread\models.py", line 1437, in append_row
    return self.append_rows(
  File "c:\projects\bot_diplom\env\lib\site-packages\gspread\models.py", line 1478, in append_rows
    return self.spreadsheet.values_append(range_label, params, body)
  File "c:\projects\bot_diplom\env\lib\site-packages\gspread\models.py", line 164, in values_append
    r = self.client.request('post', url, params=params, json=body)
  File "c:\projects\bot_diplom\env\lib\site-packages\gspread\client.py", line 61, in request
    response = getattr(self.session, method)(
  File "c:\projects\bot_diplom\env\lib\site-packages\requests\sessions.py", line 590, in post
    return self.request('POST', url, data=data, json=json, **kwargs)
  File "c:\projects\bot_diplom\env\lib\site-packages\google\auth\transport\requests.py", line 464, in request
    response = super(AuthorizedSession, self).request(
  File "c:\projects\bot_diplom\env\lib\site-packages\requests\sessions.py", line 528, in request
    prep = self.prepare_request(req)
  File "c:\projects\bot_diplom\env\lib\site-packages\requests\sessions.py", line 456, in prepare_request
    p.prepare(
  File "c:\projects\bot_diplom\env\lib\site-packages\requests\models.py", line 319, in prepare
    self.prepare_body(data, files, json)
  File "c:\projects\bot_diplom\env\lib\site-packages\requests\models.py", line 469, in prepare_body
    body = complexjson.dumps(json)
  File "C:\Users\Admin\AppData\Local\Programs\Python\Python38\lib\json\__init__.py", line 231, in dumps
    return _default_encoder.encode(obj)
  File "C:\Users\Admin\AppData\Local\Programs\Python\Python38\lib\json\encoder.py", line 199, in encode
    chunks = self.iterencode(o, _one_shot=True)
  File "C:\Users\Admin\AppData\Local\Programs\Python\Python38\lib\json\encoder.py", line 257, in iterencode
    return _iterencode(o, 0)
  File "C:\Users\Admin\AppData\Local\Programs\Python\Python38\lib\json\encoder.py", line 179, in default
    raise TypeError(f'Object of type {o.__class__.__name__} '
TypeError: Object of type datetime is not JSON serializable
INFO:telegram.ext.updater:Received signal 2 (SIGINT), stopping...
WARNING:telegram.ext.updater:Exiting immediately!
INFO:root:Бот стартовал
ERROR:telegram.ext.dispatcher:No error handlers are registered, logging exception.
Traceback (most recent call last):
  File "c:\projects\bot_diplom\env\lib\site-packages\telegram\ext\dispatcher.py", line 340, in process_update
    handler.handle_update(update, self, check, context)
  File "c:\projects\bot_diplom\env\lib\site-packages\telegram\ext\conversationhandler.py", line 465, in handle_update
    new_state = handler.handle_update(update, dispatcher, check_result, context)
  File "c:\projects\bot_diplom\env\lib\site-packages\telegram\ext\handler.py", line 119, in handle_update
    return self.callback(update, context)
  File "c:\projects\bot_diplom\anketa_prod_owner.py", line 137, in anketa_own_contacts_end
    worksheet.append_row(users.values())
  File "c:\projects\bot_diplom\env\lib\site-packages\gspread\models.py", line 1437, in append_row
    return self.append_rows(
  File "c:\projects\bot_diplom\env\lib\site-packages\gspread\models.py", line 1478, in append_rows
    return self.spreadsheet.values_append(range_label, params, body)
  File "c:\projects\bot_diplom\env\lib\site-packages\gspread\models.py", line 164, in values_append
    r = self.client.request('post', url, params=params, json=body)
  File "c:\projects\bot_diplom\env\lib\site-packages\gspread\client.py", line 61, in request
    response = getattr(self.session, method)(
  File "c:\projects\bot_diplom\env\lib\site-packages\requests\sessions.py", line 590, in post
    return self.request('POST', url, data=data, json=json, **kwargs)
  File "c:\projects\bot_diplom\env\lib\site-packages\google\auth\transport\requests.py", line 464, in request
    response = super(AuthorizedSession, self).request(
  File "c:\projects\bot_diplom\env\lib\site-packages\requests\sessions.py", line 528, in request
    prep = self.prepare_request(req)
  File "c:\projects\bot_diplom\env\lib\site-packages\requests\sessions.py", line 456, in prepare_request
    p.prepare(
  File "c:\projects\bot_diplom\env\lib\site-packages\requests\models.py", line 319, in prepare
    self.prepare_body(data, files, json)
  File "c:\projects\bot_diplom\env\lib\site-packages\requests\models.py", line 469, in prepare_body
    body = complexjson.dumps(json)
  File "C:\Users\Admin\AppData\Local\Programs\Python\Python38\lib\json\__init__.py", line 231, in dumps
    return _default_encoder.encode(obj)
  File "C:\Users\Admin\AppData\Local\Programs\Python\Python38\lib\json\encoder.py", line 199, in encode
    chunks = self.iterencode(o, _one_shot=True)
  File "C:\Users\Admin\AppData\Local\Programs\Python\Python38\lib\json\encoder.py", line 257, in iterencode
    return _iterencode(o, 0)
  File "C:\Users\Admin\AppData\Local\Programs\Python\Python38\lib\json\encoder.py", line 179, in default
    raise TypeError(f'Object of type {o.__class__.__name__} '
TypeError: Object of type dict_values is not JSON serializable
INFO:telegram.ext.updater:Received signal 2 (SIGINT), stopping...
WARNING:telegram.ext.updater:Exiting immediately!
INFO:root:Бот стартовал
ERROR:telegram.ext.dispatcher:No error handlers are registered, logging exception.
Traceback (most recent call last):
  File "c:\projects\bot_diplom\env\lib\site-packages\telegram\ext\dispatcher.py", line 340, in process_update
    handler.handle_update(update, self, check, context)
  File "c:\projects\bot_diplom\env\lib\site-packages\telegram\ext\conversationhandler.py", line 465, in handle_update
    new_state = handler.handle_update(update, dispatcher, check_result, context)
  File "c:\projects\bot_diplom\env\lib\site-packages\telegram\ext\handler.py", line 119, in handle_update
    return self.callback(update, context)
  File "c:\projects\bot_diplom\anketa_prod_owner.py", line 137, in anketa_own_contacts_end
    worksheet.append_row(asd)
  File "c:\projects\bot_diplom\env\lib\site-packages\gspread\models.py", line 1437, in append_row
    return self.append_rows(
  File "c:\projects\bot_diplom\env\lib\site-packages\gspread\models.py", line 1478, in append_rows
    return self.spreadsheet.values_append(range_label, params, body)
  File "c:\projects\bot_diplom\env\lib\site-packages\gspread\models.py", line 164, in values_append
    r = self.client.request('post', url, params=params, json=body)
  File "c:\projects\bot_diplom\env\lib\site-packages\gspread\client.py", line 61, in request
    response = getattr(self.session, method)(
  File "c:\projects\bot_diplom\env\lib\site-packages\requests\sessions.py", line 590, in post
    return self.request('POST', url, data=data, json=json, **kwargs)
  File "c:\projects\bot_diplom\env\lib\site-packages\google\auth\transport\requests.py", line 464, in request
    response = super(AuthorizedSession, self).request(
  File "c:\projects\bot_diplom\env\lib\site-packages\requests\sessions.py", line 528, in request
    prep = self.prepare_request(req)
  File "c:\projects\bot_diplom\env\lib\site-packages\requests\sessions.py", line 456, in prepare_request
    p.prepare(
  File "c:\projects\bot_diplom\env\lib\site-packages\requests\models.py", line 319, in prepare
    self.prepare_body(data, files, json)
  File "c:\projects\bot_diplom\env\lib\site-packages\requests\models.py", line 469, in prepare_body
    body = complexjson.dumps(json)
  File "C:\Users\Admin\AppData\Local\Programs\Python\Python38\lib\json\__init__.py", line 231, in dumps
    return _default_encoder.encode(obj)
  File "C:\Users\Admin\AppData\Local\Programs\Python\Python38\lib\json\encoder.py", line 199, in encode
    chunks = self.iterencode(o, _one_shot=True)
  File "C:\Users\Admin\AppData\Local\Programs\Python\Python38\lib\json\encoder.py", line 257, in iterencode
    return _iterencode(o, 0)
  File "C:\Users\Admin\AppData\Local\Programs\Python\Python38\lib\json\encoder.py", line 179, in default
    raise TypeError(f'Object of type {o.__class__.__name__} '
TypeError: Object of type dict_values is not JSON serializable
INFO:telegram.ext.updater:Received signal 2 (SIGINT), stopping...
WARNING:telegram.ext.updater:Exiting immediately!
INFO:root:Бот стартовал
ERROR:telegram.ext.dispatcher:No error handlers are registered, logging exception.
Traceback (most recent call last):
  File "c:\projects\bot_diplom\env\lib\site-packages\telegram\ext\dispatcher.py", line 340, in process_update
    handler.handle_update(update, self, check, context)
  File "c:\projects\bot_diplom\env\lib\site-packages\telegram\ext\conversationhandler.py", line 465, in handle_update
    new_state = handler.handle_update(update, dispatcher, check_result, context)
  File "c:\projects\bot_diplom\env\lib\site-packages\telegram\ext\handler.py", line 119, in handle_update
    return self.callback(update, context)
  File "c:\projects\bot_diplom\anketa_prod_owner.py", line 137, in anketa_own_contacts_end
    worksheet.append_row(asd)
  File "c:\projects\bot_diplom\env\lib\site-packages\gspread\models.py", line 1437, in append_row
    return self.append_rows(
  File "c:\projects\bot_diplom\env\lib\site-packages\gspread\models.py", line 1478, in append_rows
    return self.spreadsheet.values_append(range_label, params, body)
  File "c:\projects\bot_diplom\env\lib\site-packages\gspread\models.py", line 164, in values_append
    r = self.client.request('post', url, params=params, json=body)
  File "c:\projects\bot_diplom\env\lib\site-packages\gspread\client.py", line 61, in request
    response = getattr(self.session, method)(
  File "c:\projects\bot_diplom\env\lib\site-packages\requests\sessions.py", line 590, in post
    return self.request('POST', url, data=data, json=json, **kwargs)
  File "c:\projects\bot_diplom\env\lib\site-packages\google\auth\transport\requests.py", line 464, in request
    response = super(AuthorizedSession, self).request(
  File "c:\projects\bot_diplom\env\lib\site-packages\requests\sessions.py", line 528, in request
    prep = self.prepare_request(req)
  File "c:\projects\bot_diplom\env\lib\site-packages\requests\sessions.py", line 456, in prepare_request
    p.prepare(
  File "c:\projects\bot_diplom\env\lib\site-packages\requests\models.py", line 319, in prepare
    self.prepare_body(data, files, json)
  File "c:\projects\bot_diplom\env\lib\site-packages\requests\models.py", line 469, in prepare_body
    body = complexjson.dumps(json)
  File "C:\Users\Admin\AppData\Local\Programs\Python\Python38\lib\json\__init__.py", line 231, in dumps
    return _default_encoder.encode(obj)
  File "C:\Users\Admin\AppData\Local\Programs\Python\Python38\lib\json\encoder.py", line 199, in encode
    chunks = self.iterencode(o, _one_shot=True)
  File "C:\Users\Admin\AppData\Local\Programs\Python\Python38\lib\json\encoder.py", line 257, in iterencode
    return _iterencode(o, 0)
  File "C:\Users\Admin\AppData\Local\Programs\Python\Python38\lib\json\encoder.py", line 179, in default
    raise TypeError(f'Object of type {o.__class__.__name__} '
TypeError: Object of type datetime is not JSON serializable
INFO:telegram.ext.updater:Received signal 2 (SIGINT), stopping...
WARNING:telegram.ext.updater:Exiting immediately!
INFO:root:Бот стартовал
ERROR:telegram.ext.dispatcher:No error handlers are registered, logging exception.
Traceback (most recent call last):
  File "c:\projects\bot_diplom\env\lib\site-packages\telegram\ext\dispatcher.py", line 340, in process_update
    handler.handle_update(update, self, check, context)
  File "c:\projects\bot_diplom\env\lib\site-packages\telegram\ext\conversationhandler.py", line 465, in handle_update
    new_state = handler.handle_update(update, dispatcher, check_result, context)
  File "c:\projects\bot_diplom\env\lib\site-packages\telegram\ext\handler.py", line 119, in handle_update
    return self.callback(update, context)
  File "c:\projects\bot_diplom\anketa_prod_owner.py", line 134, in anketa_own_contacts_end
    asd = list(users.values([-1]))
TypeError: values() takes no arguments (1 given)
INFO:telegram.ext.updater:Received signal 2 (SIGINT), stopping...
WARNING:telegram.ext.updater:Exiting immediately!
INFO:root:Бот стартовал
INFO:telegram.ext.updater:Received signal 2 (SIGINT), stopping...
WARNING:telegram.ext.updater:Exiting immediately!
INFO:root:Бот стартовал
INFO:telegram.ext.updater:Received signal 2 (SIGINT), stopping...
WARNING:telegram.ext.updater:Exiting immediately!
INFO:root:Бот стартовал
ERROR:telegram.ext.dispatcher:No error handlers are registered, logging exception.
Traceback (most recent call last):
  File "c:\projects\bot_diplom\env\lib\site-packages\telegram\ext\dispatcher.py", line 340, in process_update
    handler.handle_update(update, self, check, context)
  File "c:\projects\bot_diplom\env\lib\site-packages\telegram\ext\conversationhandler.py", line 465, in handle_update
    new_state = handler.handle_update(update, dispatcher, check_result, context)
  File "c:\projects\bot_diplom\env\lib\site-packages\telegram\ext\handler.py", line 119, in handle_update
    return self.callback(update, context)
  File "c:\projects\bot_diplom\anketa_prod_owner.py", line 125, in anketa_own_contacts_end
    gc = gspread.service_account(filename= 'credentials.json')
  File "c:\projects\bot_diplom\env\lib\site-packages\gspread\auth.py", line 118, in service_account
    creds = ServiceAccountCredentials.from_service_account_file(
  File "c:\projects\bot_diplom\env\lib\site-packages\google\oauth2\service_account.py", line 227, in from_service_account_file
    info, signer = _service_account_info.from_filename(
  File "c:\projects\bot_diplom\env\lib\site-packages\google\auth\_service_account_info.py", line 72, in from_filename
    with io.open(filename, "r", encoding="utf-8") as json_file:
FileNotFoundError: [Errno 2] No such file or directory: 'credentials.json'
INFO:telegram.ext.updater:Received signal 2 (SIGINT), stopping...
WARNING:telegram.ext.updater:Exiting immediately!
INFO:root:Бот стартовал
ERROR:telegram.ext.dispatcher:No error handlers are registered, logging exception.
Traceback (most recent call last):
  File "c:\projects\bot_diplom\env\lib\site-packages\telegram\ext\dispatcher.py", line 340, in process_update
    handler.handle_update(update, self, check, context)
  File "c:\projects\bot_diplom\env\lib\site-packages\telegram\ext\conversationhandler.py", line 465, in handle_update
    new_state = handler.handle_update(update, dispatcher, check_result, context)
  File "c:\projects\bot_diplom\env\lib\site-packages\telegram\ext\handler.py", line 119, in handle_update
    return self.callback(update, context)
  File "c:\projects\bot_diplom\anketa_prod_owner.py", line 125, in anketa_own_contacts_end
    gc = gspread.service_account(filename= 'credentials.json')
  File "c:\projects\bot_diplom\env\lib\site-packages\gspread\auth.py", line 118, in service_account
    creds = ServiceAccountCredentials.from_service_account_file(
  File "c:\projects\bot_diplom\env\lib\site-packages\google\oauth2\service_account.py", line 227, in from_service_account_file
    info, signer = _service_account_info.from_filename(
  File "c:\projects\bot_diplom\env\lib\site-packages\google\auth\_service_account_info.py", line 72, in from_filename
    with io.open(filename, "r", encoding="utf-8") as json_file:
FileNotFoundError: [Errno 2] No such file or directory: 'credentials.json'
INFO:telegram.ext.updater:Received signal 2 (SIGINT), stopping...
WARNING:telegram.ext.updater:Exiting immediately!
INFO:root:Бот стартовал
ERROR:telegram.ext.dispatcher:No error handlers are registered, logging exception.
Traceback (most recent call last):
  File "c:\projects\bot_diplom\env\lib\site-packages\telegram\ext\dispatcher.py", line 340, in process_update
    handler.handle_update(update, self, check, context)
  File "c:\projects\bot_diplom\env\lib\site-packages\telegram\ext\conversationhandler.py", line 465, in handle_update
    new_state = handler.handle_update(update, dispatcher, check_result, context)
  File "c:\projects\bot_diplom\env\lib\site-packages\telegram\ext\handler.py", line 119, in handle_update
    return self.callback(update, context)
  File "c:\projects\bot_diplom\anketa_prod_owner.py", line 125, in anketa_own_contacts_end
    gc = gspread.service_account(filename= 'credentials.json')
  File "c:\projects\bot_diplom\env\lib\site-packages\gspread\auth.py", line 118, in service_account
    creds = ServiceAccountCredentials.from_service_account_file(
  File "c:\projects\bot_diplom\env\lib\site-packages\google\oauth2\service_account.py", line 227, in from_service_account_file
    info, signer = _service_account_info.from_filename(
  File "c:\projects\bot_diplom\env\lib\site-packages\google\auth\_service_account_info.py", line 72, in from_filename
    with io.open(filename, "r", encoding="utf-8") as json_file:
FileNotFoundError: [Errno 2] No such file or directory: 'credentials.json'
INFO:telegram.ext.updater:Received signal 2 (SIGINT), stopping...
WARNING:telegram.ext.updater:Exiting immediately!
INFO:root:Бот стартовал
ERROR:telegram.ext.updater:Error while getting Updates: urllib3 HTTPError ('Connection aborted.', ConnectionResetError(10054, 'Удаленный хост принудительно разорвал существующее подключение', None, 10054, None))
ERROR:telegram.ext.dispatcher:No error handlers are registered, logging exception.
Traceback (most recent call last):
  File "c:\projects\bot_diplom\env\lib\site-packages\telegram\vendor\ptb_urllib3\urllib3\connectionpool.py", line 614, in urlopen
    httplib_response = self._make_request(conn, method, url,
  File "c:\projects\bot_diplom\env\lib\site-packages\telegram\vendor\ptb_urllib3\urllib3\connectionpool.py", line 402, in _make_request
    six.raise_from(e, None)
  File "<string>", line 2, in raise_from
  File "c:\projects\bot_diplom\env\lib\site-packages\telegram\vendor\ptb_urllib3\urllib3\connectionpool.py", line 398, in _make_request
    httplib_response = conn.getresponse()
  File "C:\Users\Admin\AppData\Local\Programs\Python\Python38\lib\http\client.py", line 1347, in getresponse
    response.begin()
  File "C:\Users\Admin\AppData\Local\Programs\Python\Python38\lib\http\client.py", line 307, in begin
    version, status, reason = self._read_status()
  File "C:\Users\Admin\AppData\Local\Programs\Python\Python38\lib\http\client.py", line 268, in _read_status
    line = str(self.fp.readline(_MAXLINE + 1), "iso-8859-1")
  File "C:\Users\Admin\AppData\Local\Programs\Python\Python38\lib\socket.py", line 669, in readinto
    return self._sock.recv_into(b)
  File "C:\Users\Admin\AppData\Local\Programs\Python\Python38\lib\ssl.py", line 1241, in recv_into
    return self.read(nbytes, buffer)
  File "C:\Users\Admin\AppData\Local\Programs\Python\Python38\lib\ssl.py", line 1099, in read
    return self._sslobj.read(len, buffer)
ConnectionResetError: [WinError 10054] Удаленный хост принудительно разорвал существующее подключение

During handling of the above exception, another exception occurred:

Traceback (most recent call last):
  File "c:\projects\bot_diplom\env\lib\site-packages\telegram\utils\request.py", line 224, in _request_wrapper
    resp = self._con_pool.request(*args, **kwargs)
  File "c:\projects\bot_diplom\env\lib\site-packages\telegram\vendor\ptb_urllib3\urllib3\request.py", line 68, in request
    return self.request_encode_body(method, url, fields=fields,
  File "c:\projects\bot_diplom\env\lib\site-packages\telegram\vendor\ptb_urllib3\urllib3\request.py", line 148, in request_encode_body
    return self.urlopen(method, url, **extra_kw)
  File "c:\projects\bot_diplom\env\lib\site-packages\telegram\vendor\ptb_urllib3\urllib3\poolmanager.py", line 244, in urlopen
    response = conn.urlopen(method, u.request_uri, **kw)
  File "c:\projects\bot_diplom\env\lib\site-packages\telegram\vendor\ptb_urllib3\urllib3\connectionpool.py", line 665, in urlopen
    retries = retries.increment(method, url, error=e, _pool=self,
  File "c:\projects\bot_diplom\env\lib\site-packages\telegram\vendor\ptb_urllib3\urllib3\util\retry.py", line 347, in increment
    raise six.reraise(type(error), error, _stacktrace)
  File "c:\projects\bot_diplom\env\lib\site-packages\telegram\vendor\ptb_urllib3\urllib3\packages\six.py", line 685, in reraise
    raise value.with_traceback(tb)
  File "c:\projects\bot_diplom\env\lib\site-packages\telegram\vendor\ptb_urllib3\urllib3\connectionpool.py", line 614, in urlopen
    httplib_response = self._make_request(conn, method, url,
  File "c:\projects\bot_diplom\env\lib\site-packages\telegram\vendor\ptb_urllib3\urllib3\connectionpool.py", line 402, in _make_request
    six.raise_from(e, None)
  File "<string>", line 2, in raise_from
  File "c:\projects\bot_diplom\env\lib\site-packages\telegram\vendor\ptb_urllib3\urllib3\connectionpool.py", line 398, in _make_request
    httplib_response = conn.getresponse()
  File "C:\Users\Admin\AppData\Local\Programs\Python\Python38\lib\http\client.py", line 1347, in getresponse
    response.begin()
  File "C:\Users\Admin\AppData\Local\Programs\Python\Python38\lib\http\client.py", line 307, in begin
    version, status, reason = self._read_status()
  File "C:\Users\Admin\AppData\Local\Programs\Python\Python38\lib\http\client.py", line 268, in _read_status
    line = str(self.fp.readline(_MAXLINE + 1), "iso-8859-1")
  File "C:\Users\Admin\AppData\Local\Programs\Python\Python38\lib\socket.py", line 669, in readinto
    return self._sock.recv_into(b)
  File "C:\Users\Admin\AppData\Local\Programs\Python\Python38\lib\ssl.py", line 1241, in recv_into
    return self.read(nbytes, buffer)
  File "C:\Users\Admin\AppData\Local\Programs\Python\Python38\lib\ssl.py", line 1099, in read
    return self._sslobj.read(len, buffer)
telegram.vendor.ptb_urllib3.urllib3.exceptions.ProtocolError: ('Connection aborted.', ConnectionResetError(10054, 'Удаленный хост принудительно разорвал существующее подключение', None, 10054, None))

During handling of the above exception, another exception occurred:

Traceback (most recent call last):
  File "c:\projects\bot_diplom\env\lib\site-packages\telegram\ext\updater.py", line 379, in _network_loop_retry
    if not action_cb():
  File "c:\projects\bot_diplom\env\lib\site-packages\telegram\ext\updater.py", line 337, in polling_action_cb
    updates = self.bot.get_updates(self.last_update_id,
  File "<decorator-gen-31>", line 2, in get_updates
  File "c:\projects\bot_diplom\env\lib\site-packages\telegram\bot.py", line 67, in decorator
    result = func(*args, **kwargs)
  File "c:\projects\bot_diplom\env\lib\site-packages\telegram\bot.py", line 2138, in get_updates
    result = self._request.post(url, data, timeout=float(read_latency) + float(timeout))
  File "c:\projects\bot_diplom\env\lib\site-packages\telegram\utils\request.py", line 330, in post
    result = self._request_wrapper('POST', url,
  File "c:\projects\bot_diplom\env\lib\site-packages\telegram\utils\request.py", line 230, in _request_wrapper
    raise NetworkError('urllib3 HTTPError {}'.format(error))
telegram.error.NetworkError: urllib3 HTTPError ('Connection aborted.', ConnectionResetError(10054, 'Удаленный хост принудительно разорвал существующее подключение', None, 10054, None))
WARNING:telegram.vendor.ptb_urllib3.urllib3.connectionpool:Retrying (Retry(total=2, connect=None, read=None, redirect=None)) after connection broken by 'NewConnectionError('<telegram.vendor.ptb_urllib3.urllib3.connection.VerifiedHTTPSConnection object at 0x000001385C25D760>: Failed to establish a new connection: [Errno 11001] getaddrinfo failed')': /bot1387376270:AAFpPMnhMsZRZy1NbvVSB-iZcky3OFPniqk/getUpdates
WARNING:telegram.vendor.ptb_urllib3.urllib3.connectionpool:Retrying (Retry(total=1, connect=None, read=None, redirect=None)) after connection broken by 'NewConnectionError('<telegram.vendor.ptb_urllib3.urllib3.connection.VerifiedHTTPSConnection object at 0x000001385C25D400>: Failed to establish a new connection: [Errno 11001] getaddrinfo failed')': /bot1387376270:AAFpPMnhMsZRZy1NbvVSB-iZcky3OFPniqk/getUpdates
WARNING:telegram.vendor.ptb_urllib3.urllib3.connectionpool:Retrying (Retry(total=0, connect=None, read=None, redirect=None)) after connection broken by 'NewConnectionError('<telegram.vendor.ptb_urllib3.urllib3.connection.VerifiedHTTPSConnection object at 0x000001385C25D550>: Failed to establish a new connection: [Errno 11001] getaddrinfo failed')': /bot1387376270:AAFpPMnhMsZRZy1NbvVSB-iZcky3OFPniqk/getUpdates
ERROR:telegram.ext.updater:Error while getting Updates: urllib3 HTTPError HTTPSConnectionPool(host='api.telegram.org', port=443): Max retries exceeded with url: /bot1387376270:AAFpPMnhMsZRZy1NbvVSB-iZcky3OFPniqk/getUpdates (Caused by NewConnectionError('<telegram.vendor.ptb_urllib3.urllib3.connection.VerifiedHTTPSConnection object at 0x000001385C25DCD0>: Failed to establish a new connection: [Errno 11001] getaddrinfo failed'))
ERROR:telegram.ext.dispatcher:No error handlers are registered, logging exception.
Traceback (most recent call last):
  File "c:\projects\bot_diplom\env\lib\site-packages\telegram\vendor\ptb_urllib3\urllib3\connection.py", line 140, in _new_conn
    conn = connection.create_connection(
  File "c:\projects\bot_diplom\env\lib\site-packages\telegram\vendor\ptb_urllib3\urllib3\util\connection.py", line 60, in create_connection
    for res in socket.getaddrinfo(host, port, family, socket.SOCK_STREAM):
  File "C:\Users\Admin\AppData\Local\Programs\Python\Python38\lib\socket.py", line 918, in getaddrinfo
    for res in _socket.getaddrinfo(host, port, family, type, proto, flags):
socket.gaierror: [Errno 11001] getaddrinfo failed

During handling of the above exception, another exception occurred:

Traceback (most recent call last):
  File "c:\projects\bot_diplom\env\lib\site-packages\telegram\vendor\ptb_urllib3\urllib3\connectionpool.py", line 614, in urlopen
    httplib_response = self._make_request(conn, method, url,
  File "c:\projects\bot_diplom\env\lib\site-packages\telegram\vendor\ptb_urllib3\urllib3\connectionpool.py", line 360, in _make_request
    self._validate_conn(conn)
  File "c:\projects\bot_diplom\env\lib\site-packages\telegram\vendor\ptb_urllib3\urllib3\connectionpool.py", line 857, in _validate_conn
    super(HTTPSConnectionPool, self)._validate_conn(conn)
  File "c:\projects\bot_diplom\env\lib\site-packages\telegram\vendor\ptb_urllib3\urllib3\connectionpool.py", line 289, in _validate_conn
    conn.connect()
  File "c:\projects\bot_diplom\env\lib\site-packages\telegram\vendor\ptb_urllib3\urllib3\connection.py", line 284, in connect
    conn = self._new_conn()
  File "c:\projects\bot_diplom\env\lib\site-packages\telegram\vendor\ptb_urllib3\urllib3\connection.py", line 149, in _new_conn
    raise NewConnectionError(
telegram.vendor.ptb_urllib3.urllib3.exceptions.NewConnectionError: <telegram.vendor.ptb_urllib3.urllib3.connection.VerifiedHTTPSConnection object at 0x000001385C25DCD0>: Failed to establish a new connection: [Errno 11001] getaddrinfo failed

During handling of the above exception, another exception occurred:

Traceback (most recent call last):
  File "c:\projects\bot_diplom\env\lib\site-packages\telegram\utils\request.py", line 224, in _request_wrapper
    resp = self._con_pool.request(*args, **kwargs)
  File "c:\projects\bot_diplom\env\lib\site-packages\telegram\vendor\ptb_urllib3\urllib3\request.py", line 68, in request
    return self.request_encode_body(method, url, fields=fields,
  File "c:\projects\bot_diplom\env\lib\site-packages\telegram\vendor\ptb_urllib3\urllib3\request.py", line 148, in request_encode_body
    return self.urlopen(method, url, **extra_kw)
  File "c:\projects\bot_diplom\env\lib\site-packages\telegram\vendor\ptb_urllib3\urllib3\poolmanager.py", line 244, in urlopen
    response = conn.urlopen(method, u.request_uri, **kw)
  File "c:\projects\bot_diplom\env\lib\site-packages\telegram\vendor\ptb_urllib3\urllib3\connectionpool.py", line 691, in urlopen
    return self.urlopen(method, url, body, headers, retries,
  File "c:\projects\bot_diplom\env\lib\site-packages\telegram\vendor\ptb_urllib3\urllib3\connectionpool.py", line 691, in urlopen
    return self.urlopen(method, url, body, headers, retries,
  File "c:\projects\bot_diplom\env\lib\site-packages\telegram\vendor\ptb_urllib3\urllib3\connectionpool.py", line 691, in urlopen
    return self.urlopen(method, url, body, headers, retries,
  File "c:\projects\bot_diplom\env\lib\site-packages\telegram\vendor\ptb_urllib3\urllib3\connectionpool.py", line 665, in urlopen
    retries = retries.increment(method, url, error=e, _pool=self,
  File "c:\projects\bot_diplom\env\lib\site-packages\telegram\vendor\ptb_urllib3\urllib3\util\retry.py", line 376, in increment
    raise MaxRetryError(_pool, url, error or ResponseError(cause))
telegram.vendor.ptb_urllib3.urllib3.exceptions.MaxRetryError: HTTPSConnectionPool(host='api.telegram.org', port=443): Max retries exceeded with url: /bot1387376270:AAFpPMnhMsZRZy1NbvVSB-iZcky3OFPniqk/getUpdates (Caused by NewConnectionError('<telegram.vendor.ptb_urllib3.urllib3.connection.VerifiedHTTPSConnection object at 0x000001385C25DCD0>: Failed to establish a new connection: [Errno 11001] getaddrinfo failed'))

During handling of the above exception, another exception occurred:

Traceback (most recent call last):
  File "c:\projects\bot_diplom\env\lib\site-packages\telegram\ext\updater.py", line 379, in _network_loop_retry
    if not action_cb():
  File "c:\projects\bot_diplom\env\lib\site-packages\telegram\ext\updater.py", line 337, in polling_action_cb
    updates = self.bot.get_updates(self.last_update_id,
  File "<decorator-gen-31>", line 2, in get_updates
  File "c:\projects\bot_diplom\env\lib\site-packages\telegram\bot.py", line 67, in decorator
    result = func(*args, **kwargs)
  File "c:\projects\bot_diplom\env\lib\site-packages\telegram\bot.py", line 2138, in get_updates
    result = self._request.post(url, data, timeout=float(read_latency) + float(timeout))
  File "c:\projects\bot_diplom\env\lib\site-packages\telegram\utils\request.py", line 330, in post
    result = self._request_wrapper('POST', url,
  File "c:\projects\bot_diplom\env\lib\site-packages\telegram\utils\request.py", line 230, in _request_wrapper
    raise NetworkError('urllib3 HTTPError {}'.format(error))
telegram.error.NetworkError: urllib3 HTTPError HTTPSConnectionPool(host='api.telegram.org', port=443): Max retries exceeded with url: /bot1387376270:AAFpPMnhMsZRZy1NbvVSB-iZcky3OFPniqk/getUpdates (Caused by NewConnectionError('<telegram.vendor.ptb_urllib3.urllib3.connection.VerifiedHTTPSConnection object at 0x000001385C25DCD0>: Failed to establish a new connection: [Errno 11001] getaddrinfo failed'))
WARNING:telegram.vendor.ptb_urllib3.urllib3.connectionpool:Retrying (Retry(total=2, connect=None, read=None, redirect=None)) after connection broken by 'NewConnectionError('<telegram.vendor.ptb_urllib3.urllib3.connection.VerifiedHTTPSConnection object at 0x000001385C25D130>: Failed to establish a new connection: [Errno 11001] getaddrinfo failed')': /bot1387376270:AAFpPMnhMsZRZy1NbvVSB-iZcky3OFPniqk/getUpdates
WARNING:telegram.vendor.ptb_urllib3.urllib3.connectionpool:Retrying (Retry(total=1, connect=None, read=None, redirect=None)) after connection broken by 'NewConnectionError('<telegram.vendor.ptb_urllib3.urllib3.connection.VerifiedHTTPSConnection object at 0x000001385C25D0D0>: Failed to establish a new connection: [Errno 11001] getaddrinfo failed')': /bot1387376270:AAFpPMnhMsZRZy1NbvVSB-iZcky3OFPniqk/getUpdates
WARNING:telegram.vendor.ptb_urllib3.urllib3.connectionpool:Retrying (Retry(total=0, connect=None, read=None, redirect=None)) after connection broken by 'NewConnectionError('<telegram.vendor.ptb_urllib3.urllib3.connection.VerifiedHTTPSConnection object at 0x000001385C25D8B0>: Failed to establish a new connection: [Errno 11001] getaddrinfo failed')': /bot1387376270:AAFpPMnhMsZRZy1NbvVSB-iZcky3OFPniqk/getUpdates
ERROR:telegram.ext.updater:Error while getting Updates: urllib3 HTTPError HTTPSConnectionPool(host='api.telegram.org', port=443): Max retries exceeded with url: /bot1387376270:AAFpPMnhMsZRZy1NbvVSB-iZcky3OFPniqk/getUpdates (Caused by NewConnectionError('<telegram.vendor.ptb_urllib3.urllib3.connection.VerifiedHTTPSConnection object at 0x000001385C285220>: Failed to establish a new connection: [Errno 11001] getaddrinfo failed'))
ERROR:telegram.ext.dispatcher:No error handlers are registered, logging exception.
Traceback (most recent call last):
  File "c:\projects\bot_diplom\env\lib\site-packages\telegram\vendor\ptb_urllib3\urllib3\connection.py", line 140, in _new_conn
    conn = connection.create_connection(
  File "c:\projects\bot_diplom\env\lib\site-packages\telegram\vendor\ptb_urllib3\urllib3\util\connection.py", line 60, in create_connection
    for res in socket.getaddrinfo(host, port, family, socket.SOCK_STREAM):
  File "C:\Users\Admin\AppData\Local\Programs\Python\Python38\lib\socket.py", line 918, in getaddrinfo
    for res in _socket.getaddrinfo(host, port, family, type, proto, flags):
socket.gaierror: [Errno 11001] getaddrinfo failed

During handling of the above exception, another exception occurred:

Traceback (most recent call last):
  File "c:\projects\bot_diplom\env\lib\site-packages\telegram\vendor\ptb_urllib3\urllib3\connectionpool.py", line 614, in urlopen
    httplib_response = self._make_request(conn, method, url,
  File "c:\projects\bot_diplom\env\lib\site-packages\telegram\vendor\ptb_urllib3\urllib3\connectionpool.py", line 360, in _make_request
    self._validate_conn(conn)
  File "c:\projects\bot_diplom\env\lib\site-packages\telegram\vendor\ptb_urllib3\urllib3\connectionpool.py", line 857, in _validate_conn
    super(HTTPSConnectionPool, self)._validate_conn(conn)
  File "c:\projects\bot_diplom\env\lib\site-packages\telegram\vendor\ptb_urllib3\urllib3\connectionpool.py", line 289, in _validate_conn
    conn.connect()
  File "c:\projects\bot_diplom\env\lib\site-packages\telegram\vendor\ptb_urllib3\urllib3\connection.py", line 284, in connect
    conn = self._new_conn()
  File "c:\projects\bot_diplom\env\lib\site-packages\telegram\vendor\ptb_urllib3\urllib3\connection.py", line 149, in _new_conn
    raise NewConnectionError(
telegram.vendor.ptb_urllib3.urllib3.exceptions.NewConnectionError: <telegram.vendor.ptb_urllib3.urllib3.connection.VerifiedHTTPSConnection object at 0x000001385C285220>: Failed to establish a new connection: [Errno 11001] getaddrinfo failed

During handling of the above exception, another exception occurred:

Traceback (most recent call last):
  File "c:\projects\bot_diplom\env\lib\site-packages\telegram\utils\request.py", line 224, in _request_wrapper
    resp = self._con_pool.request(*args, **kwargs)
  File "c:\projects\bot_diplom\env\lib\site-packages\telegram\vendor\ptb_urllib3\urllib3\request.py", line 68, in request
    return self.request_encode_body(method, url, fields=fields,
  File "c:\projects\bot_diplom\env\lib\site-packages\telegram\vendor\ptb_urllib3\urllib3\request.py", line 148, in request_encode_body
    return self.urlopen(method, url, **extra_kw)
  File "c:\projects\bot_diplom\env\lib\site-packages\telegram\vendor\ptb_urllib3\urllib3\poolmanager.py", line 244, in urlopen
    response = conn.urlopen(method, u.request_uri, **kw)
  File "c:\projects\bot_diplom\env\lib\site-packages\telegram\vendor\ptb_urllib3\urllib3\connectionpool.py", line 691, in urlopen
    return self.urlopen(method, url, body, headers, retries,
  File "c:\projects\bot_diplom\env\lib\site-packages\telegram\vendor\ptb_urllib3\urllib3\connectionpool.py", line 691, in urlopen
    return self.urlopen(method, url, body, headers, retries,
  File "c:\projects\bot_diplom\env\lib\site-packages\telegram\vendor\ptb_urllib3\urllib3\connectionpool.py", line 691, in urlopen
    return self.urlopen(method, url, body, headers, retries,
  File "c:\projects\bot_diplom\env\lib\site-packages\telegram\vendor\ptb_urllib3\urllib3\connectionpool.py", line 665, in urlopen
    retries = retries.increment(method, url, error=e, _pool=self,
  File "c:\projects\bot_diplom\env\lib\site-packages\telegram\vendor\ptb_urllib3\urllib3\util\retry.py", line 376, in increment
    raise MaxRetryError(_pool, url, error or ResponseError(cause))
telegram.vendor.ptb_urllib3.urllib3.exceptions.MaxRetryError: HTTPSConnectionPool(host='api.telegram.org', port=443): Max retries exceeded with url: /bot1387376270:AAFpPMnhMsZRZy1NbvVSB-iZcky3OFPniqk/getUpdates (Caused by NewConnectionError('<telegram.vendor.ptb_urllib3.urllib3.connection.VerifiedHTTPSConnection object at 0x000001385C285220>: Failed to establish a new connection: [Errno 11001] getaddrinfo failed'))

During handling of the above exception, another exception occurred:

Traceback (most recent call last):
  File "c:\projects\bot_diplom\env\lib\site-packages\telegram\ext\updater.py", line 379, in _network_loop_retry
    if not action_cb():
  File "c:\projects\bot_diplom\env\lib\site-packages\telegram\ext\updater.py", line 337, in polling_action_cb
    updates = self.bot.get_updates(self.last_update_id,
  File "<decorator-gen-31>", line 2, in get_updates
  File "c:\projects\bot_diplom\env\lib\site-packages\telegram\bot.py", line 67, in decorator
    result = func(*args, **kwargs)
  File "c:\projects\bot_diplom\env\lib\site-packages\telegram\bot.py", line 2138, in get_updates
    result = self._request.post(url, data, timeout=float(read_latency) + float(timeout))
  File "c:\projects\bot_diplom\env\lib\site-packages\telegram\utils\request.py", line 330, in post
    result = self._request_wrapper('POST', url,
  File "c:\projects\bot_diplom\env\lib\site-packages\telegram\utils\request.py", line 230, in _request_wrapper
    raise NetworkError('urllib3 HTTPError {}'.format(error))
telegram.error.NetworkError: urllib3 HTTPError HTTPSConnectionPool(host='api.telegram.org', port=443): Max retries exceeded with url: /bot1387376270:AAFpPMnhMsZRZy1NbvVSB-iZcky3OFPniqk/getUpdates (Caused by NewConnectionError('<telegram.vendor.ptb_urllib3.urllib3.connection.VerifiedHTTPSConnection object at 0x000001385C285220>: Failed to establish a new connection: [Errno 11001] getaddrinfo failed'))
INFO:telegram.ext.updater:Received signal 2 (SIGINT), stopping...
WARNING:telegram.ext.updater:Exiting immediately!
INFO:root:Бот стартовал
INFO:telegram.ext.updater:Received signal 2 (SIGINT), stopping...
WARNING:telegram.ext.updater:Exiting immediately!
INFO:root:Бот стартовал
INFO:telegram.ext.updater:Received signal 2 (SIGINT), stopping...
WARNING:telegram.ext.updater:Exiting immediately!
INFO:root:Бот стартовал
INFO:telegram.ext.updater:Received signal 2 (SIGINT), stopping...
WARNING:telegram.ext.updater:Exiting immediately!
INFO:root:Бот стартовал
INFO:telegram.ext.updater:Received signal 2 (SIGINT), stopping...
WARNING:telegram.ext.updater:Exiting immediately!
INFO:root:Бот стартовал
INFO:telegram.ext.updater:Received signal 2 (SIGINT), stopping...
WARNING:telegram.ext.updater:Exiting immediately!
INFO:root:Бот стартовал
ERROR:telegram.ext.dispatcher:No error handlers are registered, logging exception.
Traceback (most recent call last):
  File "c:\projects\bot_diplom\env\lib\site-packages\telegram\ext\dispatcher.py", line 340, in process_update
    handler.handle_update(update, self, check, context)
  File "c:\projects\bot_diplom\env\lib\site-packages\telegram\ext\conversationhandler.py", line 465, in handle_update
    new_state = handler.handle_update(update, dispatcher, check_result, context)
  File "c:\projects\bot_diplom\env\lib\site-packages\telegram\ext\handler.py", line 119, in handle_update
    return self.callback(update, context)
  File "c:\projects\bot_diplom\anketa_prod_owner.py", line 127, in anketa_own_contacts_end
    worksheet = sh.sheet2
AttributeError: 'Spreadsheet' object has no attribute 'sheet2'
INFO:telegram.ext.updater:Received signal 2 (SIGINT), stopping...
WARNING:telegram.ext.updater:Exiting immediately!
INFO:root:Бот стартовал
ERROR:telegram.ext.dispatcher:No error handlers are registered, logging exception.
Traceback (most recent call last):
  File "c:\projects\bot_diplom\env\lib\site-packages\telegram\ext\dispatcher.py", line 340, in process_update
    handler.handle_update(update, self, check, context)
  File "c:\projects\bot_diplom\env\lib\site-packages\telegram\ext\conversationhandler.py", line 465, in handle_update
    new_state = handler.handle_update(update, dispatcher, check_result, context)
  File "c:\projects\bot_diplom\env\lib\site-packages\telegram\ext\handler.py", line 119, in handle_update
    return self.callback(update, context)
  File "c:\projects\bot_diplom\anketa_prod_owner.py", line 139, in anketa_own_contacts_end
    worksheet.append_row(avd[1:5] + asd[:-1])
AttributeError: 'NoneType' object has no attribute 'append_row'
ERROR:telegram.ext.dispatcher:No error handlers are registered, logging exception.
Traceback (most recent call last):
  File "c:\projects\bot_diplom\env\lib\site-packages\telegram\ext\dispatcher.py", line 340, in process_update
    handler.handle_update(update, self, check, context)
  File "c:\projects\bot_diplom\env\lib\site-packages\telegram\ext\conversationhandler.py", line 465, in handle_update
    new_state = handler.handle_update(update, dispatcher, check_result, context)
  File "c:\projects\bot_diplom\env\lib\site-packages\telegram\ext\handler.py", line 119, in handle_update
    return self.callback(update, context)
  File "c:\projects\bot_diplom\anketa_prod_owner.py", line 139, in anketa_own_contacts_end
    worksheet.append_row(avd[1:5] + asd[:-1])
AttributeError: 'NoneType' object has no attribute 'append_row'
INFO:telegram.ext.updater:Received signal 2 (SIGINT), stopping...
WARNING:telegram.ext.updater:Exiting immediately!
INFO:root:Бот стартовал
INFO:telegram.ext.updater:Received signal 2 (SIGINT), stopping...
WARNING:telegram.ext.updater:Exiting immediately!
INFO:root:Бот стартовал
INFO:telegram.ext.updater:Received signal 2 (SIGINT), stopping...
WARNING:telegram.ext.updater:Exiting immediately!
INFO:root:Бот стартовал
INFO:telegram.ext.updater:Received signal 2 (SIGINT), stopping...
WARNING:telegram.ext.updater:Exiting immediately!
INFO:root:Бот стартовал
INFO:telegram.ext.updater:Received signal 2 (SIGINT), stopping...
WARNING:telegram.ext.updater:Exiting immediately!
INFO:root:Бот стартовал
ERROR:telegram.ext.dispatcher:No error handlers are registered, logging exception.
Traceback (most recent call last):
  File "c:\projects\bot_diplom\env\lib\site-packages\telegram\ext\dispatcher.py", line 340, in process_update
    handler.handle_update(update, self, check, context)
  File "c:\projects\bot_diplom\env\lib\site-packages\telegram\ext\conversationhandler.py", line 465, in handle_update
    new_state = handler.handle_update(update, dispatcher, check_result, context)
  File "c:\projects\bot_diplom\env\lib\site-packages\telegram\ext\handler.py", line 119, in handle_update
    return self.callback(update, context)
  File "c:\projects\bot_diplom\anketa_applicant.py", line 146, in anketa_working_condition_end
    user_text = format_anketa(context.user_data['anketa'])
  File "c:\projects\bot_diplom\anketa_applicant.py", line 186, in format_anketa
    <b>время работы:</b> {anketa['time_work']}
KeyError: 'time_work'
INFO:telegram.ext.updater:Received signal 2 (SIGINT), stopping...
WARNING:telegram.ext.updater:Exiting immediately!
INFO:root:Бот стартовал
INFO:telegram.ext.updater:Received signal 2 (SIGINT), stopping...
WARNING:telegram.ext.updater:Exiting immediately!
INFO:root:Бот стартовал
INFO:telegram.ext.updater:Received signal 2 (SIGINT), stopping...
WARNING:telegram.ext.updater:Exiting immediately!
